Workbook

Sheet Rincian PerDin
B4: RINCIAN PERJALANAN DINAS
B5: No. : XXX/UCM-DEPT/RPD/MM/YYYY contoh 001/UCM-MNA/RPD/III/2021
B8: Berikut rincian perjalanan dinas
B9: Nama | D9: : | E9: Nama penerima tugas
B10: NIK | D10: : | E10: Nomor Induk Karyawan
B11: Jabatan | D11: : | E11: Nama Jabatan penerima tugas
B12: Departemen | D12: : | E12: Nama Departemen
B13: Tugas | D13: : | E13: Tuliskan tujuan penugasan
B14: Kota Tujuan | D14: : | E14: Jakarta, Indonesia
B15: Media Transportasi | D15: : | E15: Pesawat/Mobil/Kereta api/dll *)
B16: Berangkat | D16: : | E16: Tanggal | F16: 41712 | G16: Pukul | H16: 0.33333333
B17: Kembali | D17: : | E17: Tanggal | F17: 41716 | G17: Pukul | H17: 0.6875
B18: Durasi | D18: : | E18: =F17-F16+1 -> 5 | F18: hari
B19: Food Allowance (Uang Makan) per hari | D19: : | E19: 55000
B20: Living Allowance (Uang Saku) per hari | D20: : | E20: 60000
B21: Total Allowance (selama perjalanan dinas) | D21: :
B24: Makassar,…..
B25: Dibuat oleh, | F25: Diketahui oleh,
B29: Nama Penerima Tugas | F29: Nama Terang HCM
B30: Jabatan | F30: HCM
B34: Tembusan:
B35: 1. Departemen/Prodi
B36: 2. HCM
B37: 3. Finance
A39: Note:
A40: 1 | B40: Perjalanan dinas adalah perjalanan ke luar kota dengan jarak ≥90 km dari home base (basis awal lokasi kerja) yang dilakukan
B41: untuk kepentingan Universitas atas perintah pejabat yang berwenang
A42: 2 | B42: Rincian Perjalanan Dinas adalah dokumen yang berisi perincian perjalanan dinas perorangan beserta perhitungan food & living allowance
A43: 3 | B43: "Rincian Perjalanan Dinas", selanjutnya disebut "Rincian PerDin"
A44: 4 | B44: Perhitungan Food & Living allowance mengacu pada ketentuan yang berlaku
A45: 5 | B45: Dokumen pendukung pengajuan RF perjalanan dinas:
B46: 5.1 Surat Tugas
B47: 5.2 Rincian PerDin

Sheet PJK PerDin DN IDR
B2: LAPORAN BIAYA PERJALANAN DINAS
H3: No. RF.: | I3: Tuliskan nomor RF
B4: Nama | C4: ='Rincian PerDin'!E9 -> Nama penerima tugas | F4: Jabatan | G4: ='Rincian PerDin'!E11 -> Nama Jabatan penerima tugas | J4: Autolink dengan Rincian PerDin
B5: NIK | C5: ='Rincian PerDin'!E10 -> Nomor Induk Karyawan | F5: Departemen | G5: ='Rincian PerDin'!E12 -> Nama Departemen
B6: Kota Tujuan | C6: ='Rincian PerDin'!E14 -> Jakarta, Indonesia
B7: Tugas | C7: ='Rincian PerDin'!E13 -> Tuliskan tujuan penugasan
B8: Berangkat | C8: Tanggal | D8: ='Rincian PerDin'!F16 -> 41712 | E8: Pukul | F8: ='Rincian PerDin'!H16 -> 0.33333333
B9: Kembali | C9: Tanggal | D9: ='Rincian PerDin'!F17 -> 41716 | E9: Pukul | F9: ='Rincian PerDin'!H17 -> 0.6875
B10: Durasi | C10: =D9-D8+1 -> 5 | D10: hari
B12: Biaya Perjalanan Dinas
B13: Hari | C13: Tanggal | D13: Living Allowance (Uang Saku) | E13: Food Allowance (Uang Makan) | F13: Transport | H13: Others | J13: Keterangan
F14: Jenis Biaya | G14: Biaya | H14: Jenis Biaya | I14: Biaya
B15: Senin | C15: 41712 | D15: 50000 | E15: 40000 | F15: Airport tax | G15: 40000 | H15: - | I15: - | J15: Nota….
B16: Selasa | C16: 41713 | D16: 50000 | E16: 40000 | F16: Taxi & tol Hotel ke Lokasi Seminar | G16: 100000 | H16: - | I16: - | J16: Nota….
F17: Taxi & tol Lokasi Seminar ke Hotel | G17: 105000 | H17: - | I17: - | J17: Nota….
B18: Rabu | C18: 41714 | D18: 50000 | E18: 40000 | F18: Taxi & tol Hotel ke Lokasi Seminar | G18: 100000 | H18: - | I18: - | J18: Nota….
B19: Kamis | C19: 41715 | D19: 50000 | E19: 40000 | F19: - | G19: - | H19: Sewa mobil | I19: 400000 | J19: Nota….
H20: Insentif Driver | I20: 75000 | J20: Nota….
B21: Jumat | C21: 41716 | D21: 50000 | E21: 40000 | F21: Airport tax | G21: 40000 | H21: - | I21: - | J21: Nota….
B23: Sub Total | D23: =SUM(D15:D22) -> 250000 | E23: =SUM(E15:E22) -> 200000 | G23: =SUM(G15:G22) -> 385000 | I23: =SUM(I15:I22) -> 475000
B24: Total | D24: =D23+E23+G23+I23 -> 1310000
B29: Biaya Entertainment
B30: Hari | C30: Tanggal | D30: Jenis Entertainment | F30: Nama Tamu | H30: Jabatan Tamu | J30: Biaya
B31: Kamis | C31: 41715 | D31: Makan malam | F31: Prof. Mustijab | H31: Kepala Dinas Pendidikan Jakarta | J31: 750000
D32: Bingkisan | J32: 250000
B34: Total | J34: =SUM(J31:J33) -> 1000000
B36: Uang Muka | D36: 3000000
B37: Realisasi Biaya | D37: =D24+J34 -> 2310000
B38: Selisih | D38: =D36-D37 -> 690000
B39: Keterangan | D39: =IF(D36>D37,"Bayar ke Perusahaan",IF(D37=D36,"Nilai telah Sesuai","Bayar ke Karyawan")) -> Bayar ke Perusahaan
B41: Makassar,…..
B42: Dibuat oleh, | G42: Disetujui oleh,
B46: Nama Karyawan yang Perjalanan Dinas | G46: Nama Atasan 1 (minimal HOD level)
B47: Jabatan | G47: Jabatan
A50: Note:
A51: 1 | B51: "Laporan Pertanggungjawaban Perjalanan Dinas" selanjutnya disebut "PJK PerDin"
A52: 2 | B52: PJK PerDin dibuat perorangan
A53: 3 | B53: Untuk efisiensi proses verifikasi, bukti pendukung pengeluaran (nota/kuitansi) wajib dilampirkan dan diberi nomor
A54: 4 | B54: Pihak yang menyetujui PJK PerDin minimal adalah HOD level
A55: 5 | B55: Serahkan PJK PerDin yang telah mendapat persetujuan ke F&A selambat-lambatnya 3 hari kerja setelah tanggal kembali

Sheet PJK PerDin LN
G2: Beri contoh 3 mata uang
B3: LAPORAN BIAYA PERJALANAN DINAS
I4: No. RF.: | J4: Tuliskan nomor RF
B5: Nama | C5: ='Rincian PerDin'!E9 -> Nama penerima tugas | F5: Jabatan | G5: ='Rincian PerDin'!E11 -> Nama Jabatan penerima tugas | J5: Autolink dengan Rincian PerDin
B6: NIK | C6: ='Rincian PerDin'!E10 -> Nomor Induk Karyawan | F6: Departemen | G6: ='Rincian PerDin'!E12 -> Nama Departemen
B7: Kota Tujuan | C7: ='Rincian PerDin'!E14 -> Jakarta, Indonesia
B8: Tugas | C8: ='Rincian PerDin'!E13 -> Tuliskan tujuan penugasan
B9: Berangkat | C9: Tanggal | D9: ='Rincian PerDin'!F16 -> 41712 | E9: Pukul | F9: ='Rincian PerDin'!H16 -> 0.33333333
B10: Kembali | C10: Tanggal | D10: ='Rincian PerDin'!F17 -> 41716 | E10: Pukul | F10: ='Rincian PerDin'!H17 -> 0.6875
B11: Durasi | C11: =D10-D9+1 -> 5 | D11: hari
B13: Biaya Perjalanan Dinas
B14: Hari | C14: Tanggal | D14: Living Allowance (Uang Saku) | E14: Food Allowance (Uang Makan) | F14: Transport | I14: Others | K14: Keterangan
F15: Jenis Biaya | G15: Biaya | I15: Jenis Biaya | J15: Biaya
B16: Senin | C16: 41712 | D16: 50000 | E16: 40000 | F16: Airport tax | G16: 40000 | H16: - | I16: - | K16: Nota….
B17: Selasa | C17: 41713 | D17: 50000 | E17: 40000 | F17: Taxi & tol Hotel ke Lokasi Seminar | G17: - | H17: 20 | I17: - | K17: Nota….
F18: Taxi & tol Lokasi Seminar ke Hotel | G18: - | H18: 21 | I18: - | K18: Nota….
B19: Rabu | C19: 41714 | D19: 50000 | E19: 40000 | F19: Taxi & tol Hotel ke Lokasi Seminar | G19: - | H19: 20 | I19: - | K19: Nota….
B20: Kamis | C20: 41715 | D20: 50000 | E20: 40000 | F20: - | G20: - | H20: - | I20: Sewa mobil | J20: 40 | K20: Nota….
I21: Insentif Driver | J21: 8 | K21: Nota….
B22: Jumat | C22: 41716 | D22: 50000 | E22: 40000 | F22: Airport tax | G22: - | I22: - | K22: Nota….
B24: Sub Total | D24: =SUM(D16:D23) -> 250000 | E24: =SUM(E16:E23) -> 200000 | G24: =SUM(G16:G23) -> 40000 | H24: =SUM(H16:H23) -> 61 | J24: =SUM(J16:J23) -> 48
B25: Total | D25: =D24+E24+G24+J24 -> 490048
B30: Biaya Entertainment
B31: Hari | C31: Tanggal | D31: Jenis Entertainment | F31: Nama Tamu | I31: Jabatan Tamu | K31: Biaya
B32: Kamis | C32: 41715 | D32: Makan malam | F32: Prof. Mustijab | I32: Kepala Dinas Pendidikan Jakarta | K32: 750000
D33: Bingkisan | K33: 250000
B35: Total | K35: =SUM(K32:K34) -> 1000000
B37: Uang Muka | D37: 3000000
B38: Realisasi Biaya | D38: =D25+K35 -> 1490048
B39: Selisih | D39: =D37-D38 -> 1509952
B40: Keterangan | D40: =IF(D37>D38,"Bayar ke Perusahaan",IF(D38=D37,"Nilai telah Sesuai","Bayar ke Karyawan")) -> Bayar ke Perusahaan
B42: Makassar,…..
B43: Dibuat oleh, | G43: Disetujui oleh,
B47: Nama Karyawan yang Perjalanan Dinas | G47: Nama Atasan 1 (minimal HOD level)
B48: Jabatan | G48: Jabatan
A51: Note:
A52: 1 | B52: "Laporan Pertanggungjawaban Perjalanan Dinas" selanjutnya disebut "PJK PerDin"
A53: 2 | B53: PJK PerDin dibuat perorangan
A54: 3 | B54: Untuk efisiensi proses verifikasi, bukti pendukung pengeluaran (nota/kuitansi) wajib dilampirkan dan diberi nomor
A55: 4 | B55: Pihak yang menyetujui PJK PerDin minimal adalah HOD level
...
